#VRML_SIM R2023b utf8

EXTERNPROTO "https://raw.githubusercontent.com/cyberbotics/webots/R2023b/projects/objects/backgrounds/protos/TexturedBackground.proto"
EXTERNPROTO "https://raw.githubusercontent.com/cyberbotics/webots/R2023b/projects/objects/backgrounds/protos/TexturedBackgroundLight.proto"
EXTERNPROTO "https://raw.githubusercontent.com/cyberbotics/webots/R2023b/projects/objects/floors/protos/RectangleArena.proto"

WorldInfo {
}
Viewpoint {
  orientation -0.35917002393659125 -0.14770759763232388 0.921509283462232 3.866090250403388
  position 0.759713046792451 0.9467285259214413 1.1962622391329596
}
TexturedBackground {
}
TexturedBackgroundLight {
}
RectangleArena {
  rotation 0.7071067811865475 0 0.7071067811865475 0
  floorSize 2 2
}
Robot {
  children [
    DEF Body Pose {
      translation 0 0 0.0415
      children [
        Shape {
          appearance PBRAppearance {
            baseColor 0.2 0.8 0.6
            metalness 0
          }
          geometry Cylinder {
            height 0.08
            radius 0.045
          }
        }
      ]
    }
    HingeJoint {
      jointParameters HingeJointParameters {
        anchor 0.045 0 0.025
      }
      device [
        RotationalMotor {
          name "Motor_1"
        }
      ]
      endPoint Solid {
        translation 0.045 0 0.025
        rotation 0 1 0 1.57
        children [
          DEF wheel Shape {
            appearance PBRAppearance {
              baseColor 1 1 0.8
              roughness 1
              metalness 0
            }
            geometry Cylinder {
              height 0.01
              radius 0.025
            }
          }
        ]
        boundingObject USE wheel
        physics DEF wheel_physics Physics {
        }
      }
    }
    HingeJoint {
      jointParameters HingeJointParameters {
        anchor -0.045 0 0.025
      }
      device [
        RotationalMotor {
          name "Motor_2"
        }
      ]
      endPoint Solid {
        translation -0.045 0 0.025
        rotation 0 1 0 1.57
        children [
          USE wheel
        ]
        name "solid(1)"
        boundingObject USE wheel
        physics USE wheel_physics
      }
    }
  ]
  boundingObject USE Body
  controller "uts"
}
